2023-12-14 10:22:46,642 CRIT Supervisor is running as root.  Privileges were not dropped because no user is specified in the config file.  If you intend to run as root, you can set user=root in the config file to avoid this message.
2023-12-14 10:22:46,643 INFO supervisord started with pid 7
2023-12-14 10:22:47,648 INFO spawned: 'app' with pid 8
2023-12-14 10:22:47,651 INFO spawned: 'nginx' with pid 9
Bottle v0.12.25 server starting up (using WSGIRefServer())...
Listening on http://localhost:5000/
Hit Ctrl-C to quit.

2023-12-14 10:22:48,755 INFO success: app entered RUNNING state, process has stayed up for > than 1 seconds (startsecs)
2023-12-14 10:22:48,756 INFO success: nginx entered RUNNING state, process has stayed up for > than 1 seconds (startsecs)
[CTRL] POST /setup
[Time: 14.12.23 10:22:50] [Level: info] id: 1601f627cb85db52
[Time: 14.12.23 10:22:50] [Level: info] coordinator: True
[Time: 14.12.23 10:22:50] [Level: info] clients: ['1601f627cb85db52']
[Time: 14.12.23 10:22:50] [Level: info] state: initial
[Time: 14.12.23 10:22:50] [Level: info] [State: initial] Reding config file
127.0.0.1 - - [14/Dec/2023 10:22:50] "POST /api/setup HTTP/1.0" 200 0
[Time: 14.12.23 10:22:50] [Level: info] [State: initial] curent dire: ['opt', 'mnt', 'proc', 'home', 'etc', 'root', 'media', 'run', 'usr', 'bin', 'srv', 'boot', 'lib', 'tmp', 'dev', 'sys', 'var', 'sbin', 'app', 'supervisord.log', 'supervisord.pid', '.dockerenv', 'entrypoint.sh', 'supervisord.conf']
[Time: 14.12.23 10:22:50] [Level: info] Traceback (most recent call last):
  File "/root/.local/lib/python3.8/site-packages/FeatureCloud/app/engine/app.py", line 226, in guarded_run
    self.run()
  File "/root/.local/lib/python3.8/site-packages/FeatureCloud/app/engine/app.py", line 241, in run
    transition = self.current_state.run()
  File "/app/states.py", line 27, in run
    config = bios.read(f'data/tests/config.yml')
  File "/root/.local/lib/python3.8/site-packages/bios/base.py", line 54, in read
    return read_functions[file_type](file_name, delimiter)
  File "/root/.local/lib/python3.8/site-packages/bios/base.py", line 47, in read_yaml
    return io_object.read(file_name)
  File "/root/.local/lib/python3.8/site-packages/bios/operations/yaml_io.py", line 7, in read
    f = open(file_name, "r")
FileNotFoundError: [Errno 2] No such file or directory: 'data/tests/config.yml'

[CTRL] GET /status
127.0.0.1 - - [14/Dec/2023 10:22:50] "GET /api/status HTTP/1.0" 200 153
